16:21 李明憲 通常，因為一次抓10個URL的內容後，都會把內容新增到資料庫中(比如EXCEL新增一行)
16:22 李明憲 如果新增到EXCEL這個動作是寫在content() {}裡面
16:22 李明憲 10個URL都成功抓到內容，也就會都成功寫入到excel
16:22 李明憲 也不會跑到catch()
16:23 李明憲 但萬一有一個url抓失敗，EXCEL就只會新增9筆資料
16:23 李明憲 這個失敗的我們就會需要知道是哪一個，然後重新抓
16:23 李明憲 但這一切都要程式自己執行
16:24 李明憲 可是呢，當沒有在new promise()後面加上.catch()的時候，他會跑到try catch()的catch()裡面
16:25 李明憲 然後 catch(){  }  只會進去執行一次裡面的程式
16:26 李明憲 因為我們沒有寫迴圈之類的，所以合理推敲，這個catch {} 的執行指有一次
16:27 李明憲 所以如果，有2個URL錯誤，這裡又只執行1次
16:27 李明憲 就會丟失另一個
16:27 李明憲 沒機會抓出來到底有哪些失敗的
16:29 李明憲 但已知 promise.all()會按照順序返回所有的執行結果
16:29 李明憲已收回訊息
16:29 李明憲 但必須得是都成功的情況才會返回
16:30 李明憲 那我們就照目前這樣寫，符合他的特性
16:31 李明憲 就能在results拿到成功與失敗的結果
16:31 李明憲 然後就能抓出來失敗的是誰，然後再寫程式去重新執行